<sdf version="1.6">
  <model name="parallelogram">
    <link name="link_A1">
      <pose>0 0 0 0 0 0</pose>
      <inertial>
        <pose>0 0 0 0 0 0</pose>
        <mass>10</mass>
        <inertia>
          <ixx>0.008416666667</ixx>
          <iyy>0.841666666667</iyy>
          <izz>0.833416666667</izz>
          <ixy>0.</ixy>
          <ixz>0.</ixz>
          <iyz>0.</iyz>
        </inertia>
      </inertial>
      <visual name="link_A1_visual">
        <geometry>
          <cylinder>
            <length>1.0</length>
            <radius>0.05</radius>
          </cylinder>
        </geometry>
      </visual>
    </link>

    <link name="link_B1">
      <pose>0.8 0 0 0 0 0</pose>
      <inertial>
        <pose>0 0 0 0 0 0</pose>
        <mass>5</mass>
        <inertia>
          <ixx>0.0042083333333</ixx>
          <iyy>0.1541666666667</iyy>
          <izz>0.1500416666667</izz>
          <ixy>0</ixy>
          <ixz>0</ixz>
          <iyz>0</iyz>
        </inertia>
      </inertial>
      <visual name="link_B1_visual">
        <geometry>
          <cylinder>
            <length>0.6</length>
            <radius>0.05</radius>
          </cylinder>
        </geometry>
      </visual>
    </link>

    <link name="link_A2">
      <pose>1.6 0 0 0 0 0</pose>
      <inertial>
        <pose>0 0 0 0 0 0</pose>
        <mass>10</mass>
        <inertia>
          <ixx>0.008416666667</ixx>
          <iyy>0.841666666667</iyy>
          <izz>0.833416666667</izz>
          <ixy>0.</ixy>
          <ixz>0.</ixz>
          <iyz>0.</iyz>
        </inertia>
      </inertial>
      <visual name="link_A2_visual">
        <geometry>
          <cylinder>
            <length>1.0</length>
            <radius>0.05</radius>
          </cylinder>
        </geometry>
      </visual>
    </link>

    <link name="link_B2">
      <pose>2.4 0 0 0 0 0</pose>
      <inertial>
        <pose>0 0 0 0 0 0</pose>
        <mass>5</mass>
        <inertia>
          <ixx>0.0042083333333</ixx>
          <iyy>0.1541666666667</iyy>
          <izz>0.1500416666667</izz>
          <ixy>0</ixy>
          <ixz>0</ixz>
          <iyz>0</iyz>
        </inertia>
      </inertial>
      <visual name="link_B2_visual">
        <geometry>
          <cylinder>
            <length>0.6</length>
            <radius>0.05</radius>
          </cylinder>
        </geometry>
      </visual>
    </link>

    <joint name="joint_B1" type="revolute">
      <pose>-0.3 0 0 0 0 0</pose>
      <child>link_B1</child>
      <parent>link_A1</parent>
      <axis>
        <xyz>0 1 0</xyz>
        <use_parent_model_frame>1</use_parent_model_frame>
      </axis>
    </joint>

    <joint name="joint_A2" type="revolute">
      <pose>-0.5 0 0 0 0 0</pose>
      <child>link_A2</child>
      <parent>link_B1</parent>
      <axis>
        <xyz>0 1 0</xyz>
        <use_parent_model_frame>1</use_parent_model_frame>
      </axis>
    </joint>

    <joint name="joint_B2" type="revolute">
      <pose>-0.3 0 0 0 0 0</pose>
      <child>link_B2</child>
      <parent>link_A2</parent>
      <axis>
        <xyz>0 1 0</xyz>
        <use_parent_model_frame>1</use_parent_model_frame>
      </axis>
    </joint>

  </model>
</sdf>
