<robot name="drc_skeleton">
    <link name="head">
        <inertial>
            <mass value="3.751" />
            <origin xyz="-0.0481 0 0.0457" rpy="0 -0 0" />
            <inertia ixx="0.0108" ixy="-0.0001" ixz="-0.0007" iyy="0.0182" iyz="-0.0003" izz="0.0108" />
        </inertial>
    </link>
    <link name="l_clav">
        <inertial>
            <mass value="3.45" />
            <origin xyz="0 0.048 -0.084" rpy="0 -0 0" />
            <inertia ixx="0.011" ixy="0" ixz="0" iyy="0.009" iyz="-0.004" izz="0.004" />
        </inertial>
    </link>
    <link name="l_foot">
        <inertial>
            <mass value="2.05" />
            <origin xyz="0.027 0 -0.067" rpy="0 -0 0" />
            <inertia ixx="0.002" ixy="0" ixz="0" iyy="0.007" iyz="0" izz="0.008" />
        </inertial>
    </link>
    <link name="l_hand">
        <inertial>
            <mass value="0.53" />
            <origin xyz="0 0.06 0" rpy="0 -0 0" />
            <inertia ixx="0.00265" ixy="0" ixz="0" iyy="0.00446" iyz="0" izz="0.00446" />
        </inertial>
    </link>
    <link name="l_larm">
        <inertial>
            <mass value="2.509" />
            <origin xyz="0 0 0" rpy="0 -0 0" />
            <inertia ixx="0.00265" ixy="0" ixz="0" iyy="0.00446" iyz="0" izz="0.00446" />
        </inertial>
    </link>
    <link name="l_lfarm">
        <inertial>
            <mass value="2.65" />
            <origin xyz="0 -0.07 0" rpy="0 -0 0" />
            <inertia ixx="0.007" ixy="0" ixz="0" iyy="0.004" iyz="0" izz="0.007" />
        </inertial>
    </link>
    <link name="l_lglut">
        <inertial>
            <mass value="0.866" />
            <origin xyz="0.0133341 0.0170484 -0.0312052" rpy="0 -0 0" />
            <inertia ixx="0.000691326" ixy="-2.24344e-05" ixz="2.50508e-06" iyy="0.00126856" iyz="0.000137862" izz="0.00106487" />
        </inertial>
    </link>
    <link name="l_lleg">
        <inertial>
            <mass value="5.479" />
            <origin xyz="0.001 0 -0.187" rpy="0 -0 0" />
            <inertia ixx="0.077" ixy="0" ixz="-0.003" iyy="0.076" iyz="0" izz="0.01" />
        </inertial>
    </link>
    <link name="l_scap">
        <inertial>
            <mass value="3.012" />
            <origin xyz="0 0 0" rpy="0 -0 0" />
            <inertia ixx="0.00319" ixy="0" ixz="0" iyy="0.00583" iyz="0" izz="0.00583" />
        </inertial>
    </link>
    <link name="l_talus">
        <inertial>
            <mass value="0.125" />
            <origin xyz="0 0 0" rpy="0 -0 0" />
            <inertia ixx="1.01674e-05" ixy="0" ixz="0" iyy="8.42775e-06" iyz="0" izz="1.30101e-05" />
        </inertial>
    </link>
    <link name="l_uarm">
        <inertial>
            <mass value="3.388" />
            <origin xyz="0 -0.065 0" rpy="0 -0 0" />
            <inertia ixx="0.00656" ixy="0" ixz="0" iyy="0.00358" iyz="0" izz="0.00656" />
        </inertial>
    </link>
    <link name="l_ufarm">
        <inertial>
            <mass value="2.12" />
            <origin xyz="0 -0.2 0" rpy="0 -0 0" />
            <inertia ixx="0.006" ixy="0" ixz="0" iyy="0.003" iyz="0" izz="0.006" />
        </inertial>
    </link>
    <link name="l_uglut">
        <inertial>
            <mass value="0.648" />
            <origin xyz="0.00529262 -0.00344732 0.00313046" rpy="0 -0 0" />
            <inertia ixx="0.00074276" ixy="-3.79607e-08" ixz="-2.79549e-05" iyy="0.000688179" iyz="-3.2735e-08" izz="0.00041242" />
        </inertial>
    </link>
    <link name="l_uleg">
        <inertial>
            <mass value="9.209" />
            <origin xyz="0 0 -0.21" rpy="0 -0 0" />
            <inertia ixx="0.09" ixy="0" ixz="0" iyy="0.09" iyz="0" izz="0.02" />
        </inertial>
    </link>
    <link name="ltorso">
        <inertial>
            <mass value="2.409" />
            <origin xyz="-0.0112984 -3.15366e-06 0.0746835" rpy="0 -0 0" />
            <inertia ixx="0.0039092" ixy="-5.04491e-08" ixz="-0.000342157" iyy="0.00341694" iyz="4.87119e-07" izz="0.00174492" />
        </inertial>
    </link>
    <link name="mtorso">
        <inertial>
            <mass value="0.69" />
            <origin xyz="-0.00816266 -0.0131245 0.0305974" rpy="0 -0 0" />
            <inertia ixx="0.000454181" ixy="-6.10764e-05" ixz="3.94009e-05" iyy="0.000483282" iyz="5.27463e-05" izz="0.000444215" />
        </inertial>
    </link>
    <link name="pelvis">
        <inertial>
            <mass value="17.882" />
            <origin xyz="0.0111 0 0.0271" rpy="0 -0 0" />
            <inertia ixx="0.1244" ixy="0.0008" ixz="-0.0007" iyy="0.0958" iyz="-0.0005" izz="0.1167" />
        </inertial>
    </link>
    <link name="r_clav">
        <inertial>
            <mass value="3.45" />
            <origin xyz="0 -0.048 -0.084" rpy="0 -0 0" />
            <inertia ixx="0.011" ixy="0" ixz="0" iyy="0.009" iyz="0.004" izz="0.004" />
        </inertial>
    </link>
    <link name="r_foot">
        <inertial>
            <mass value="2.05" />
            <origin xyz="0.027 0 -0.067" rpy="0 -0 0" />
            <inertia ixx="0.002" ixy="0" ixz="0" iyy="0.007" iyz="0" izz="0.008" />
        </inertial>
    </link>
    <link name="r_hand">
        <inertial>
            <mass value="0.53" />
            <origin xyz="0 -0.06 0" rpy="0 -0 0" />
            <inertia ixx="0.00265" ixy="0" ixz="0" iyy="0.00446" iyz="0" izz="0.00446" />
        </inertial>
    </link>
    <link name="r_larm">
        <inertial>
            <mass value="2.509" />
            <origin xyz="0 0 0" rpy="0 -0 0" />
            <inertia ixx="0.00265" ixy="0" ixz="0" iyy="0.00446" iyz="0" izz="0.00446" />
        </inertial>
    </link>
    <link name="r_lfarm">
        <inertial>
            <mass value="2.65" />
            <origin xyz="0 0.07 0" rpy="0 -0 0" />
            <inertia ixx="0.007" ixy="0" ixz="0" iyy="0.004" iyz="0" izz="0.007" />
        </inertial>
    </link>
    <link name="r_lglut">
        <inertial>
            <mass value="0.866" />
            <origin xyz="0.0133341 -0.0170484 -0.0312052" rpy="0 -0 0" />
            <inertia ixx="0.000691326" ixy="2.24344e-05" ixz="2.50508e-06" iyy="0.00126856" iyz="-0.000137862" izz="0.00106487" />
        </inertial>
    </link>
    <link name="r_lleg">
        <inertial>
            <mass value="5.479" />
            <origin xyz="0.001 0 -0.187" rpy="0 -0 0" />
            <inertia ixx="0.077" ixy="-0" ixz="-0.003" iyy="0.076" iyz="-0" izz="0.01" />
        </inertial>
    </link>
    <link name="r_scap">
        <inertial>
            <mass value="3.012" />
            <origin xyz="0 0 0" rpy="0 -0 0" />
            <inertia ixx="0.00319" ixy="0" ixz="0" iyy="0.00583" iyz="0" izz="0.00583" />
        </inertial>
    </link>
    <link name="r_talus">
        <inertial>
            <mass value="0.125" />
            <origin xyz="0 0 0" rpy="0 -0 0" />
            <inertia ixx="1.01674e-05" ixy="0" ixz="0" iyy="8.42775e-06" iyz="0" izz="1.30101e-05" />
        </inertial>
    </link>
    <link name="r_uarm">
        <inertial>
            <mass value="3.388" />
            <origin xyz="0 0.065 0" rpy="0 -0 0" />
            <inertia ixx="0.00656" ixy="0" ixz="0" iyy="0.00358" iyz="0" izz="0.00656" />
        </inertial>
    </link>
    <link name="r_ufarm">
        <inertial>
            <mass value="2.12" />
            <origin xyz="0 0.2 0" rpy="0 -0 0" />
            <inertia ixx="0.006" ixy="0" ixz="0" iyy="0.003" iyz="0" izz="0.006" />
        </inertial>
    </link>
    <link name="r_uglut">
        <inertial>
            <mass value="0.648" />
            <origin xyz="0.00529262 0.00344732 0.00313046" rpy="0 -0 0" />
            <inertia ixx="0.00074276" ixy="3.79607e-08" ixz="-2.79549e-05" iyy="0.000688179" iyz="3.2735e-08" izz="0.00041242" />
        </inertial>
    </link>
    <link name="r_uleg">
        <inertial>
            <mass value="9.209" />
            <origin xyz="0 0 -0.21" rpy="0 -0 0" />
            <inertia ixx="0.09" ixy="0" ixz="0" iyy="0.09" iyz="0" izz="0.02" />
        </inertial>
    </link>
    <link name="utorso">
        <inertial>
            <mass value="63.73" />
            <origin xyz="-0.0581 0 0.3056" rpy="0 -0 0" />
            <inertia ixx="1.466" ixy="0.00362" ixz="0.336" iyy="1.51" iyz="0.001" izz="1.3" />
        </inertial>
    </link>
    <joint name="back_bkx" type="revolute">
        <origin xyz="0 0 0.05" rpy="0 -0 0" />
        <axis xyz="1 0 0" />
        <parent link="mtorso" />
        <child link="utorso" />
        <dynamics damping="0.1" friction="0" />
        <limit effort="300" velocity="12" lower="-0.523599" upper="0.523599" />
        <safety_controller k_position="100" k_velocity="100" soft_lower_limit="-10.5236" soft_upper_limit="10.5236" />
    </joint>
    <joint name="back_bky" type="revolute">
        <origin xyz="0 0 0.162" rpy="0 -0 0" />
        <axis xyz="0 1 0" />
        <parent link="ltorso" />
        <child link="mtorso" />
        <dynamics damping="0.1" friction="0" />
        <limit effort="445" velocity="9" lower="-0.219388" upper="0.538783" />
        <safety_controller k_position="100" k_velocity="100" soft_lower_limit="-10.2194" soft_upper_limit="10.5388" />
    </joint>
    <joint name="back_bkz" type="revolute">
        <origin xyz="-0.0125 0 0" rpy="0 -0 0" />
        <axis xyz="0 0 1" />
        <parent link="pelvis" />
        <child link="ltorso" />
        <dynamics damping="0.1" friction="0" />
        <limit effort="106" velocity="12" lower="-0.663225" upper="0.663225" />
        <safety_controller k_position="100" k_velocity="100" soft_lower_limit="-10.6632" soft_upper_limit="10.6632" />
    </joint>
    <joint name="l_arm_elx" type="revolute">
        <origin xyz="0 0.119 0.0092" rpy="0 -0 0" />
        <axis xyz="1 0 0" />
        <parent link="l_uarm" />
        <child link="l_larm" />
        <dynamics damping="0.1" friction="0" />
        <limit effort="112" velocity="12" lower="0" upper="2.35619" />
        <safety_controller k_position="100" k_velocity="100" soft_lower_limit="-10" soft_upper_limit="12.3562" />
    </joint>
    <joint name="l_arm_ely" type="revolute">
        <origin xyz="0 0.187 0.016" rpy="0 -0 0" />
        <axis xyz="0 1 0" />
        <parent link="l_scap" />
        <child link="l_uarm" />
        <dynamics damping="0.1" friction="0" />
        <limit effort="63" velocity="12" lower="0" upper="3.14159" />
        <safety_controller k_position="100" k_velocity="100" soft_lower_limit="-10" soft_upper_limit="13.1416" />
    </joint>
    <joint name="l_arm_shx" type="revolute">
        <origin xyz="0 0.0981 -0.2511" rpy="0 -0 0" />
        <axis xyz="1 0 0" />
        <parent link="l_clav" />
        <child link="l_scap" />
        <dynamics damping="0.1" friction="0" />
        <limit effort="99" velocity="12" lower="-1.5708" upper="1.5708" />
        <safety_controller k_position="100" k_velocity="100" soft_lower_limit="-11.5708" soft_upper_limit="11.5708" />
    </joint>
    <joint name="l_arm_shz" type="revolute">
        <origin xyz="0.1406 0.2036 0.4776" rpy="0 -0 0" />
        <axis xyz="0 0 1" />
        <parent link="utorso" />
        <child link="l_clav" />
        <dynamics damping="0.1" friction="0" />
        <limit effort="87" velocity="12" lower="-1.5708" upper="0.785398" />
        <safety_controller k_position="100" k_velocity="100" soft_lower_limit="-11.5708" soft_upper_limit="10.7854" />
    </joint>
    <joint name="l_arm_wrx" type="revolute">
        <origin xyz="0 0 0" rpy="0 -0 0" />
        <axis xyz="1 0 0" />
        <parent link="l_ufarm" />
        <child link="l_lfarm" />
        <dynamics damping="0.1" friction="0" />
        <limit effort="25" velocity="10" lower="-1.7628" upper="1.7628" />
        <safety_controller k_position="100" k_velocity="100" soft_lower_limit="-11.7628" soft_upper_limit="11.7628" />
    </joint>
    <joint name="l_arm_wry" type="revolute">
        <origin xyz="0 -0.29955 -0.00921" rpy="0 -0 0" />
        <axis xyz="0 1 0" />
        <parent link="l_larm" />
        <child link="l_ufarm" />
        <dynamics damping="0.1" friction="0" />
        <limit effort="25" velocity="10" lower="-3.011" upper="3.011" />
        <safety_controller k_position="100" k_velocity="100" soft_lower_limit="-13.011" soft_upper_limit="13.011" />
    </joint>
    <joint name="l_arm_wry2" type="revolute">
        <origin xyz="0 0 0" rpy="0 -0 0" />
        <axis xyz="0 1 0" />
        <parent link="l_lfarm" />
        <child link="l_hand" />
        <dynamics damping="0.1" friction="0" />
        <limit effort="25" velocity="10" lower="-2.9671" upper="2.9671" />
        <safety_controller k_position="100" k_velocity="100" soft_lower_limit="-12.9671" soft_upper_limit="12.9671" />
    </joint>
    <joint name="l_leg_akx" type="revolute">
        <origin xyz="0 0 0" rpy="0 -0 0" />
        <axis xyz="1 0 0" />
        <parent link="l_talus" />
        <child link="l_foot" />
        <dynamics damping="0.1" friction="0" />
        <limit effort="360" velocity="12" lower="-0.8" upper="0.8" />
        <safety_controller k_position="100" k_velocity="100" soft_lower_limit="-10.8" soft_upper_limit="10.8" />
    </joint>
    <joint name="l_leg_aky" type="revolute">
        <origin xyz="0 0 -0.422" rpy="0 -0 0" />
        <axis xyz="0 1 0" />
        <parent link="l_lleg" />
        <child link="l_talus" />
        <dynamics damping="0.1" friction="0" />
        <limit effort="740" velocity="12" lower="-1" upper="0.7" />
        <safety_controller k_position="100" k_velocity="100" soft_lower_limit="-11" soft_upper_limit="10.7" />
    </joint>
    <joint name="l_leg_hpx" type="revolute">
        <origin xyz="0 0 0" rpy="0 -0 0" />
        <axis xyz="1 0 0" />
        <parent link="l_uglut" />
        <child link="l_lglut" />
        <dynamics damping="0.1" friction="0" />
        <limit effort="530" velocity="12" lower="-0.523599" upper="0.523599" />
        <safety_controller k_position="100" k_velocity="100" soft_lower_limit="-10.5236" soft_upper_limit="10.5236" />
    </joint>
    <joint name="l_leg_hpy" type="revolute">
        <origin xyz="0.05 0.0225 -0.066" rpy="0 -0 0" />
        <axis xyz="0 1 0" />
        <parent link="l_lglut" />
        <child link="l_uleg" />
        <dynamics damping="0.1" friction="0" />
        <limit effort="840" velocity="12" lower="-1.61234" upper="0.65764" />
        <safety_controller k_position="100" k_velocity="100" soft_lower_limit="-11.6123" soft_upper_limit="10.6576" />
    </joint>
    <joint name="l_leg_hpz" type="revolute">
        <origin xyz="0 0.089 0" rpy="0 -0 0" />
        <axis xyz="0 0 1" />
        <parent link="pelvis" />
        <child link="l_uglut" />
        <dynamics damping="0.1" friction="0" />
        <limit effort="275" velocity="12" lower="-0.174358" upper="0.786794" />
        <safety_controller k_position="100" k_velocity="100" soft_lower_limit="-10.1744" soft_upper_limit="10.7868" />
    </joint>
    <joint name="l_leg_kny" type="revolute">
        <origin xyz="-0.05 0 -0.374" rpy="0 -0 0" />
        <axis xyz="0 1 0" />
        <parent link="l_uleg" />
        <child link="l_lleg" />
        <dynamics damping="0.1" friction="0" />
        <limit effort="890" velocity="12" lower="0" upper="2.35637" />
        <safety_controller k_position="100" k_velocity="100" soft_lower_limit="-10" soft_upper_limit="12.3564" />
    </joint>
    <joint name="neck_ry" type="revolute">
        <origin xyz="0.2546 0 0.6215" rpy="0 -0 0" />
        <axis xyz="0 1 0" />
        <parent link="utorso" />
        <child link="head" />
        <dynamics damping="0.1" friction="0" />
        <limit effort="25" velocity="6.28" lower="-0.602139" upper="1.14319" />
        <safety_controller k_position="100" k_velocity="100" soft_lower_limit="-10.6021" soft_upper_limit="11.1432" />
    </joint>
    <joint name="r_arm_elx" type="revolute">
        <origin xyz="0 -0.119 0.0092" rpy="0 -0 0" />
        <axis xyz="1 0 0" />
        <parent link="r_uarm" />
        <child link="r_larm" />
        <dynamics damping="0.1" friction="0" />
        <limit effort="112" velocity="12" lower="-2.35619" upper="0" />
        <safety_controller k_position="100" k_velocity="100" soft_lower_limit="-12.3562" soft_upper_limit="10" />
    </joint>
    <joint name="r_arm_ely" type="revolute">
        <origin xyz="0 -0.187 0.016" rpy="0 -0 0" />
        <axis xyz="0 1 0" />
        <parent link="r_scap" />
        <child link="r_uarm" />
        <dynamics damping="0.1" friction="0" />
        <limit effort="63" velocity="12" lower="0" upper="3.14159" />
        <safety_controller k_position="100" k_velocity="100" soft_lower_limit="-10" soft_upper_limit="13.1416" />
    </joint>
    <joint name="r_arm_shx" type="revolute">
        <origin xyz="0 -0.0981 -0.2511" rpy="0 -0 0" />
        <axis xyz="1 0 0" />
        <parent link="r_clav" />
        <child link="r_scap" />
        <dynamics damping="0.1" friction="0" />
        <limit effort="99" velocity="12" lower="-1.5708" upper="1.5708" />
        <safety_controller k_position="100" k_velocity="100" soft_lower_limit="-11.5708" soft_upper_limit="11.5708" />
    </joint>
    <joint name="r_arm_shz" type="revolute">
        <origin xyz="0.1406 -0.2036 0.4776" rpy="0 -0 0" />
        <axis xyz="0 0 1" />
        <parent link="utorso" />
        <child link="r_clav" />
        <dynamics damping="0.1" friction="0" />
        <limit effort="87" velocity="12" lower="-0.785398" upper="1.5708" />
        <safety_controller k_position="100" k_velocity="100" soft_lower_limit="-10.7854" soft_upper_limit="11.5708" />
    </joint>
    <joint name="r_arm_wrx" type="revolute">
        <origin xyz="0 0 0" rpy="0 -0 0" />
        <axis xyz="1 0 0" />
        <parent link="r_ufarm" />
        <child link="r_lfarm" />
        <dynamics damping="0.1" friction="0" />
        <limit effort="25" velocity="10" lower="-1.7628" upper="1.7628" />
        <safety_controller k_position="100" k_velocity="100" soft_lower_limit="-11.7628" soft_upper_limit="11.7628" />
    </joint>
    <joint name="r_arm_wry" type="revolute">
        <origin xyz="0 0.29955 -0.00921" rpy="0 -0 0" />
        <axis xyz="0 1 0" />
        <parent link="r_larm" />
        <child link="r_ufarm" />
        <dynamics damping="0.1" friction="0" />
        <limit effort="25" velocity="10" lower="-3.011" upper="3.011" />
        <safety_controller k_position="100" k_velocity="100" soft_lower_limit="-13.011" soft_upper_limit="13.011" />
    </joint>
    <joint name="r_arm_wry2" type="revolute">
        <origin xyz="0 0 0" rpy="0 -0 0" />
        <axis xyz="0 1 0" />
        <parent link="r_lfarm" />
        <child link="r_hand" />
        <dynamics damping="0.1" friction="0" />
        <limit effort="25" velocity="10" lower="-2.9671" upper="2.9671" />
        <safety_controller k_position="100" k_velocity="100" soft_lower_limit="-12.9671" soft_upper_limit="12.9671" />
    </joint>
    <joint name="r_leg_akx" type="revolute">
        <origin xyz="0 0 0" rpy="0 -0 0" />
        <axis xyz="1 0 0" />
        <parent link="r_talus" />
        <child link="r_foot" />
        <dynamics damping="0.1" friction="0" />
        <limit effort="360" velocity="12" lower="-0.8" upper="0.8" />
        <safety_controller k_position="100" k_velocity="100" soft_lower_limit="-10.8" soft_upper_limit="10.8" />
    </joint>
    <joint name="r_leg_aky" type="revolute">
        <origin xyz="0 0 -0.422" rpy="0 -0 0" />
        <axis xyz="0 1 0" />
        <parent link="r_lleg" />
        <child link="r_talus" />
        <dynamics damping="0.1" friction="0" />
        <limit effort="740" velocity="12" lower="-1" upper="0.7" />
        <safety_controller k_position="100" k_velocity="100" soft_lower_limit="-11" soft_upper_limit="10.7" />
    </joint>
    <joint name="r_leg_hpx" type="revolute">
        <origin xyz="0 0 0" rpy="0 -0 0" />
        <axis xyz="1 0 0" />
        <parent link="r_uglut" />
        <child link="r_lglut" />
        <dynamics damping="0.1" friction="0" />
        <limit effort="530" velocity="12" lower="-0.523599" upper="0.523599" />
        <safety_controller k_position="100" k_velocity="100" soft_lower_limit="-10.5236" soft_upper_limit="10.5236" />
    </joint>
    <joint name="r_leg_hpy" type="revolute">
        <origin xyz="0.05 -0.0225 -0.066" rpy="0 -0 0" />
        <axis xyz="0 1 0" />
        <parent link="r_lglut" />
        <child link="r_uleg" />
        <dynamics damping="0.1" friction="0" />
        <limit effort="840" velocity="12" lower="-1.61234" upper="0.65764" />
        <safety_controller k_position="100" k_velocity="100" soft_lower_limit="-11.6123" soft_upper_limit="10.6576" />
    </joint>
    <joint name="r_leg_hpz" type="revolute">
        <origin xyz="0 -0.089 0" rpy="0 -0 0" />
        <axis xyz="0 0 1" />
        <parent link="pelvis" />
        <child link="r_uglut" />
        <dynamics damping="0.1" friction="0" />
        <limit effort="275" velocity="12" lower="-0.786794" upper="0.174358" />
        <safety_controller k_position="100" k_velocity="100" soft_lower_limit="-10.7868" soft_upper_limit="10.1744" />
    </joint>
    <joint name="r_leg_kny" type="revolute">
        <origin xyz="-0.05 0 -0.374" rpy="0 -0 0" />
        <axis xyz="0 1 0" />
        <parent link="r_uleg" />
        <child link="r_lleg" />
        <dynamics damping="0.1" friction="0" />
        <limit effort="890" velocity="12" lower="0" upper="2.35637" />
        <safety_controller k_position="100" k_velocity="100" soft_lower_limit="-10" soft_upper_limit="12.3564" />
    </joint>

    <!-- Shadow hand on left-arm -->
     <link name="sr_left_wrist">
        <visual>
            <geometry name="wrist_visual">
                <mesh filename="package://shadow_hand_ign/meshes/visual/wrist.dae"/>
            </geometry>
        </visual>
        <collision>
            <geometry name="wrist_collision">
                <mesh filename="package://shadow_hand_ign/meshes/collision/wrist.stl"/>
            </geometry>
        </collision>
    </link>

    <link name="sr_left_palm">
        <visual>
            <geometry name="palm_visual">
                <mesh filename="package://shadow_hand_ign/meshes/visual/palm.dae"/>
            </geometry>
        </visual>
        <collision>
            <geometry name="palm_collision">
                <mesh filename="package://shadow_hand_ign/meshes/collision/palm.stl"/>
            </geometry>
        </collision>
    </link>


    <!-- Forearm-Wrist Joints -->
    <joint name="l_hand_joint" type="revolute">
        <parent link="l_hand"/>
        <child link="sr_left_wrist"/>
        <origin rpy="0 0 0" xyz="0 -0.010 0.213"/>
        <axis xyz="0 1 0"/>
        <limit effort="10.0" lower="-0.523598775598" upper="0.174532925199" velocity="2.0"/>
    </joint>

    <joint name="sr_left_wrist_joint" type="revolute">
        <parent link="sr_left_wrist"/>
        <child link="sr_left_palm"/>
        <origin rpy="0 0 0" xyz="0 0 0.034"/>
        <axis xyz="1 0 0"/>
        <limit effort="5.0" lower="-0.698131700798" upper="0.488692190558" velocity="2.0"/>
    </joint>


    <!-- Thumb Links -->
    <link name="sr_left_thumb_base"/>

    <link name="sr_left_thumb_proximal">
        <visual>
            <geometry name="thumb_proximal_visual">
                <mesh filename="package://shadow_hand_ign/meshes/visual/thumb_proximal.dae"/>
            </geometry>
        </visual>
        <collision>
            <geometry name="thumb_proximal_collision">
                <mesh filename="package://shadow_hand_ign/meshes/collision/thumb_proximal.stl"/>
            </geometry>
        </collision>
    </link>

    <link name="sr_left_thumb_hub"/>

    <link name="sr_left_thumb_middle">
        <visual>
            <geometry name="thumb_middle_visual">
                <mesh filename="package://shadow_hand_ign/meshes/visual/thumb_middle.dae"/>
            </geometry>
        </visual>
        <collision>
            <geometry name="thumb_middle_collision">
                <mesh filename="package://shadow_hand_ign/meshes/collision/thumb_middle.stl"/>
            </geometry>
        </collision>
    </link>

    <link name="sr_left_thumb_distal">
        <visual>
            <geometry name="thumb_distal_visual">
                <mesh filename="package://shadow_hand_ign/meshes/visual/thumb_distal.dae"/>
            </geometry>
        </visual>
        <collision>
            <geometry name="thumb_distal_collision">
                <mesh filename="package://shadow_hand_ign/meshes/collision/thumb_distal.stl"/>
            </geometry>
        </collision>
    </link>


    <!-- Thumb Joints -->
    <joint name="sr_left_thumb_joint1" type="revolute">
        <parent link="sr_left_palm"/>
        <child link="sr_left_thumb_base"/>
        <origin rpy="0 0.785398163397 0.0" xyz="0.034 -0.0085 0.029"/>
        <axis xyz="0 0 -1"/>
        <limit effort="4.0" lower="-1.0471975512" upper="1.0471975512" velocity="4.0"/>
    </joint>

    <joint name="sr_left_thumb_joint2" type="revolute">
        <parent link="sr_left_thumb_base"/>
        <child link="sr_left_thumb_proximal"/>
        <axis xyz="1 0 0"/>
        <limit effort="4.0" lower="0.0" upper="1.2217304764" velocity="4.0"/>
    </joint>

    <joint name="sr_left_thumb_joint3" type="revolute">
        <parent link="sr_left_thumb_proximal"/>
        <child link="sr_left_thumb_hub"/>
        <origin rpy="0 0 0" xyz="0 0 0.038"/>
        <axis xyz="1 0 0"/>
        <limit effort="4.0" lower="-0.209439510239" upper="0.209439510239" velocity="4.0"/>
    </joint>

    <joint name="sr_left_thumb_joint4" type="revolute">
        <parent link="sr_left_thumb_hub"/>
        <child link="sr_left_thumb_middle"/>
        <axis xyz="0 -1 0"/>
        <limit effort="4.0" lower="-0.698131700798" upper="0.698131700798" velocity="2.0"/>
    </joint>

    <joint name="sr_left_thumb_joint5" type="revolute">
        <parent link="sr_left_thumb_middle"/>
        <child link="sr_left_thumb_distal"/>
        <origin rpy="0 0 -1.57079632679" xyz="0 0 0.032"/>
        <axis xyz="1 0 0"/>
        <limit effort="4.0" lower="0" upper="1.57079632679" velocity="4.0"/>
    </joint>


    <!-- Index Finger Links -->
    <link name="sr_left_index_finger_knuckle">
        <visual>
            <origin rpy="0 0 0" xyz="0 0 0.0005"/>
            <geometry name="index_finger_knuckle_visual">
                <mesh filename="package://shadow_hand_ign/meshes/visual/knuckle.dae"/>
            </geometry>
        </visual>
        <collision>
            <origin rpy="0 0 0" xyz="0 0 0.0005"/>
            <geometry name="index_finger_knuckle_collision">
                <mesh filename="package://shadow_hand_ign/meshes/collision/knuckle.stl"/>
            </geometry>
        </collision>
    </link>

    <link name="sr_left_index_finger_proximal">
        <visual>
            <geometry name="index_finger_proximal_visual">
                <mesh filename="package://shadow_hand_ign/meshes/visual/finger_proximal.dae"/>
            </geometry>
        </visual>
        <collision>
            <geometry name="index_finger_proximal_collision">
                <mesh filename="package://shadow_hand_ign/meshes/collision/finger_proximal.stl"/>
            </geometry>
        </collision>
    </link>

    <link name="sr_left_index_finger_middle">
        <visual>
            <geometry name="index_finger_middle_visual">
                <mesh filename="package://shadow_hand_ign/meshes/visual/finger_middle.dae"/>
            </geometry>
        </visual>
        <collision>
            <geometry name="index_finger_middle_collision">
                <mesh filename="package://shadow_hand_ign/meshes/collision/finger_middle.stl"/>
            </geometry>
        </collision>
    </link>

    <link name="sr_left_index_finger_distal">
        <visual>
            <geometry name="index_finger_distal_visual">
                <mesh filename="package://shadow_hand_ign/meshes/visual/finger_distal.dae"/>
            </geometry>
        </visual>
        <collision>
            <geometry name="index_finger_distal_collision">
                <mesh filename="package://shadow_hand_ign/meshes/collision/finger_distal.stl"/>
            </geometry>
        </collision>
    </link>


    <!-- Index Finger Joints -->
    <joint name="sr_left_index_finger_joint1" type="revolute">
        <parent link="sr_left_palm"/>
        <child link="sr_left_index_finger_knuckle"/>
        <origin rpy="0 0 0" xyz="0.033 0 0.095"/>
        <axis xyz="0 -1 0"/>
        <limit effort="4.0" lower="-0.349065850399" upper="0.349065850399" velocity="2.0"/>
    </joint>

    <joint name="sr_left_index_finger_join2" type="revolute">
        <parent link="sr_left_index_finger_knuckle"/>
        <child link="sr_left_index_finger_proximal"/>
        <axis xyz="1 0 0"/>
        <limit effort="4.0" lower="0" upper="1.57079632679" velocity="2.0"/>
    </joint>

    <joint name="sr_left_index_finger_joint3" type="revolute">
        <parent link="sr_left_index_finger_proximal"/>
        <child link="sr_left_index_finger_middle"/>
        <origin rpy="0 0 0" xyz="0 0 0.045"/>
        <axis xyz="1 0 0"/>
        <limit effort="4.0" lower="0" upper="1.57079632679" velocity="2.0"/>
    </joint>

    <joint name="sr_left_index_finger_joint4" type="revolute">
        <parent link="sr_left_index_finger_middle"/>
        <child link="sr_left_index_finger_distal"/>
        <origin rpy="0 0 0" xyz="0 0 0.025"/>
        <axis xyz="1 0 0"/>
        <limit effort="4.0" lower="0" upper="1.57079632679" velocity="2.0"/>
    </joint>


    <!-- Middle Finger Links -->
    <link name="sr_left_middle_finger_knuckle">
        <visual>
            <origin rpy="0 0 0" xyz="0 0 0.0005"/>
            <geometry name="middle_finger_knuckle_visual">
                <mesh filename="package://shadow_hand_ign/meshes/visual/knuckle.dae"/>
            </geometry>
        </visual>
        <collision>
            <origin rpy="0 0 0" xyz="0 0 0.0005"/>
            <geometry name="middle_finger_knuckle_collision">
                <mesh filename="package://shadow_hand_ign/meshes/collision/knuckle.stl"/>
            </geometry>
        </collision>
    </link>

    <link name="sr_left_middle_finger_proximal">
        <visual>
            <geometry name="middle_finger_proximal_visual">
                <mesh filename="package://shadow_hand_ign/meshes/visual/finger_proximal.dae"/>
            </geometry>
        </visual>
        <collision>
            <geometry name="middle_finger_proximal_collision">
                <mesh filename="package://shadow_hand_ign/meshes/collision/finger_proximal.stl"/>
            </geometry>
        </collision>
    </link>

    <link name="sr_left_middle_finger_middle">
        <visual>
            <geometry name="middle_finger_middle_visual">
                <mesh filename="package://shadow_hand_ign/meshes/visual/finger_middle.dae"/>
            </geometry>
        </visual>
        <collision>
            <geometry name="middle_finger_middle_collision">
                <mesh filename="package://shadow_hand_ign/meshes/collision/finger_middle.stl"/>
            </geometry>
        </collision>
    </link>

    <link name="sr_left_middle_finger_distal">
        <visual>
            <geometry name="middle_finger_distal_visual">
                <mesh filename="package://shadow_hand_ign/meshes/visual/finger_distal.dae"/>
            </geometry>
        </visual>
        <collision>
            <geometry name="middle_finger_distal_collision">
                <mesh filename="package://shadow_hand_ign/meshes/collision/finger_distal.stl"/>
            </geometry>
        </collision>
    </link>


    <!-- Middle Finger Joints -->
    <joint name="sr_left_middle_finger_joint1" type="revolute">
        <parent link="sr_left_palm"/>
        <child link="sr_left_middle_finger_knuckle"/>
        <origin rpy="0 0 0" xyz="0.011 0 0.099"/>
        <axis xyz="0 -1 0"/>
        <limit effort="4.0" lower="-0.349065850399" upper="0.349065850399" velocity="2.0"/>
    </joint>

    <joint name="sr_left_middle_finger_joint2" type="revolute">
        <parent link="sr_left_middle_finger_knuckle"/>
        <child link="sr_left_middle_finger_proximal"/>
        <axis xyz="1 0 0"/>
        <limit effort="4.0" lower="0" upper="1.57079632679" velocity="2.0"/>
    </joint>

    <joint name="sr_left_middle_finger_joint3" type="revolute">
        <parent link="sr_left_middle_finger_proximal"/>
        <child link="sr_left_middle_finger_middle"/>
        <origin rpy="0 0 0" xyz="0 0 0.045"/>
        <axis xyz="1 0 0"/>
        <limit effort="4.0" lower="0" upper="1.57079632679" velocity="2.0"/>
    </joint>

    <joint name="sr_left_middle_finger_joint4" type="revolute">
        <parent link="sr_left_middle_finger_middle"/>
        <child link="sr_left_middle_finger_distal"/>
        <origin rpy="0 0 0" xyz="0 0 0.025"/>
        <axis xyz="1 0 0"/>
        <limit effort="4.0" lower="0" upper="1.57079632679" velocity="2.0"/>
    </joint>


    <!-- Ring Finger Links -->
    <link name="sr_left_ring_finger_knuckle">
        <visual>
            <origin rpy="0 0 0" xyz="0 0 0.0005"/>
            <geometry name="ring_finger_knuckle_visual">
                <mesh filename="package://shadow_hand_ign/meshes/visual/knuckle.dae"/>
            </geometry>
        </visual>
        <collision>
            <origin rpy="0 0 0" xyz="0 0 0.0005"/>
            <geometry name="ring_finger_knuckle_collision">
                <mesh filename="package://shadow_hand_ign/meshes/collision/knuckle.stl"/>
            </geometry>
        </collision>
    </link>

    <link name="sr_left_ring_finger_proximal">
        <visual>
            <geometry name="ring_finger_proximal_visual">
                <mesh filename="package://shadow_hand_ign/meshes/visual/finger_proximal.dae"/>
            </geometry>
        </visual>
        <collision>
            <geometry name="ring_finger_proximal_collision">
                <mesh filename="package://shadow_hand_ign/meshes/collision/finger_proximal.stl"/>
            </geometry>
        </collision>
    </link>

    <link name="sr_left_ring_finger_middle">
        <visual>
            <geometry name="ring_finger_middle_visual">
                <mesh filename="package://shadow_hand_ign/meshes/visual/finger_middle.dae"/>
            </geometry>
        </visual>
        <collision>
            <geometry name="ring_finger_middle_collision">
                <mesh filename="package://shadow_hand_ign/meshes/collision/finger_middle.stl"/>
            </geometry>
        </collision>
    </link>

    <link name="sr_left_ring_finger_distal">
        <visual>
            <geometry name="ring_finger_distal_visual">
                <mesh filename="package://shadow_hand_ign/meshes/visual/finger_distal.dae"/>
            </geometry>
        </visual>
        <collision>
            <geometry name="ring_finger_distal_collision">
                <mesh filename="package://shadow_hand_ign/meshes/collision/finger_distal.stl"/>
            </geometry>
        </collision>
    </link>


    <!-- Ring Finger Joints -->
    <joint name="sr_left_ring_finger_joint1" type="revolute">
        <parent link="sr_left_palm"/>
        <child link="sr_left_ring_finger_knuckle"/>
        <origin rpy="0 0 0" xyz="-0.011 0 0.095"/>
        <axis xyz="0 1 0"/>
        <limit effort="4.0" lower="-0.349065850399" upper="0.349065850399" velocity="2.0"/>
    </joint>

    <joint name="sr_left_ring_finger_joint2" type="revolute">
        <parent link="sr_left_ring_finger_knuckle"/>
        <child link="sr_left_ring_finger_proximal"/>
        <axis xyz="1 0 0"/>
        <limit effort="4.0" lower="0" upper="1.57079632679" velocity="2.0"/>
    </joint>

    <joint name="sr_left_ring_finger_joint3" type="revolute">
        <parent link="sr_left_ring_finger_proximal"/>
        <child link="sr_left_ring_finger_middle"/>
        <origin rpy="0 0 0" xyz="0 0 0.045"/>
        <axis xyz="1 0 0"/>
        <limit effort="4.0" lower="0" upper="1.57079632679" velocity="2.0"/>
    </joint>

    <joint name="sr_left_ring_finger_joint4" type="revolute">
        <parent link="sr_left_ring_finger_middle"/>
        <child link="sr_left_ring_finger_distal"/>
        <origin rpy="0 0 0" xyz="0 0 0.025"/>
        <axis xyz="1 0 0"/>
        <limit effort="4.0" lower="0" upper="1.57079632679" velocity="2.0"/>
    </joint>


    <!-- Little Finger Links -->
    <link name="sr_left_little_finger_metacarpal">
        <visual>
            <geometry name="little_finger_metacarpal_visual">
                <mesh filename="package://shadow_hand_ign/meshes/visual/metacarpal.dae"/>
            </geometry>
        </visual>
        <collision>
            <geometry name="little_finger_metacarpal_collision">
                <mesh filename="package://shadow_hand_ign/meshes/collision/metacarpal.stl"/>
            </geometry>
        </collision>
    </link>

    <link name="sr_left_little_finger_knuckle">
        <visual>
            <origin rpy="0 0 0" xyz="0 0 0.0005"/>
            <geometry name="little_finger_knuckle_visual">
                <mesh filename="package://shadow_hand_ign/meshes/visual/knuckle.dae"/>
            </geometry>
        </visual>
        <collision>
            <origin rpy="0 0 0" xyz="0 0 0.0005"/>
            <geometry name="little_finger_knuckle_collision">
                <mesh filename="package://shadow_hand_ign/meshes/collision/knuckle.stl"/>
            </geometry>
        </collision>
    </link>

    <link name="sr_left_little_finger_proximal">
        <visual>
            <geometry name="little_finger_proximal_visual">
                <mesh filename="package://shadow_hand_ign/meshes/visual/finger_proximal.dae"/>
            </geometry>
        </visual>
        <collision>
            <geometry name="little_finger_proximal_collision">
                <mesh filename="package://shadow_hand_ign/meshes/collision/finger_proximal.stl"/>
            </geometry>
        </collision>
    </link>

    <link name="sr_left_little_finger_middle">
        <visual>
            <geometry name="little_finger_middle_visual">
                <mesh filename="package://shadow_hand_ign/meshes/visual/finger_middle.dae"/>
            </geometry>
        </visual>
        <collision>
            <geometry name="little_finger_middle_collision">
                <mesh filename="package://shadow_hand_ign/meshes/collision/finger_middle.stl"/>
            </geometry>
        </collision>
    </link>

    <link name="sr_left_little_finger_distal">
        <visual>
            <geometry name="little_finger_distal_visual">
                <mesh filename="package://shadow_hand_ign/meshes/visual/finger_distal.dae"/>
            </geometry>
        </visual>
        <collision>
            <geometry name="little_finger_distal_collision">
                <mesh filename="package://shadow_hand_ign/meshes/collision/finger_distal.stl"/>
            </geometry>
        </collision>
    </link>


    <!-- Little Finger Joints -->
    <joint name="sr_left_little_finger_joint1" type="revolute">
        <parent link="sr_left_palm"/>
        <child link="sr_left_little_finger_metacarpal"/>
        <origin rpy="0 0 0" xyz="-0.033 0 0.02071"/>
        <axis xyz="0.573576436 0 0.819152044"/>
        <limit effort="4.0" lower="0" upper="0.785398163397" velocity="2.0"/>
    </joint>

    <joint name="sr_left_little_finger_joint2" type="revolute">
        <parent link="sr_left_little_finger_metacarpal"/>
        <child link="sr_left_little_finger_knuckle"/>
        <origin rpy="0 0 0" xyz="0 0 0.06579"/>
        <axis xyz="0 1 0"/>
        <limit effort="4.0" lower="-0.349065850399" upper="0.349065850399" velocity="2.0"/>
    </joint>

    <joint name="sr_left_little_finger_joint3" type="revolute">
        <parent link="sr_left_little_finger_knuckle"/>
        <child link="sr_left_little_finger_proximal"/>
        <axis xyz="1 0 0"/>
        <limit effort="4.0" lower="0" upper="1.57079632679" velocity="2.0"/>
    </joint>

    <joint name="sr_left_little_finger_joint4" type="revolute">
        <parent link="sr_left_little_finger_proximal"/>
        <child link="sr_left_little_finger_middle"/>
        <origin rpy="0 0 0" xyz="0 0 0.045"/>
        <axis xyz="1 0 0"/>
        <limit effort="4.0" lower="0" upper="1.57079632679" velocity="2.0"/>
    </joint>

    <joint name="sr_left_little_finger_joint5" type="revolute">
        <parent link="sr_left_little_finger_middle"/>
        <child link="sr_left_little_finger_distal"/>
        <origin rpy="0 0 0" xyz="0 0 0.025"/>
        <axis xyz="1 0 0"/>
        <limit effort="4.0" lower="0" upper="1.57079632679" velocity="2.0"/>
    </joint>


    <!-- SR connected to right arm -->

    <!-- Forearm-Wrist-Palm Links -->

    <link name="sr_right_wrist">
        <visual>
            <geometry name="wrist_visual">
                <mesh filename="package://shadow_hand_ign/meshes/visual/wrist.dae"/>
            </geometry>
        </visual>
        <collision>
            <geometry name="wrist_collision">
                <mesh filename="package://shadow_hand_ign/meshes/collision/wrist.stl"/>
            </geometry>
        </collision>
    </link>

    <link name="sr_right_palm">
        <visual>
            <geometry name="palm_visual">
                <mesh filename="package://shadow_hand_ign/meshes/visual/palm.dae"/>
            </geometry>
        </visual>
        <collision>
            <geometry name="palm_collision">
                <mesh filename="package://shadow_hand_ign/meshes/collision/palm.stl"/>
            </geometry>
        </collision>
    </link>


    <!-- Forearm-Wrist Joints -->
    <joint name="r_hand_joint" type="revolute">
        <parent link="r_hand"/>
        <child link="sr_right_wrist"/>
        <origin rpy="0 0 0" xyz="0 -0.010 0.213"/>
        <axis xyz="0 1 0"/>
        <limit effort="10.0" lower="-0.523598775598" upper="0.174532925199" velocity="2.0"/>
    </joint>

    <joint name="sr_right_wrist_joint" type="revolute">
        <parent link="sr_right_wrist"/>
        <child link="sr_right_palm"/>
        <origin rpy="0 0 0" xyz="0 0 0.034"/>
        <axis xyz="1 0 0"/>
        <limit effort="5.0" lower="-0.698131700798" upper="0.488692190558" velocity="2.0"/>
    </joint>


    <!-- Thumb Links -->
    <link name="sr_right_thumb_base"/>

    <link name="sr_right_thumb_proximal">
        <visual>
            <geometry name="thumb_proximal_visual">
                <mesh filename="package://shadow_hand_ign/meshes/visual/thumb_proximal.dae"/>
            </geometry>
        </visual>
        <collision>
            <geometry name="thumb_proximal_collision">
                <mesh filename="package://shadow_hand_ign/meshes/collision/thumb_proximal.stl"/>
            </geometry>
        </collision>
    </link>

    <link name="sr_right_thumb_hub"/>

    <link name="sr_right_thumb_middle">
        <visual>
            <geometry name="thumb_middle_visual">
                <mesh filename="package://shadow_hand_ign/meshes/visual/thumb_middle.dae"/>
            </geometry>
        </visual>
        <collision>
            <geometry name="thumb_middle_collision">
                <mesh filename="package://shadow_hand_ign/meshes/collision/thumb_middle.stl"/>
            </geometry>
        </collision>
    </link>

    <link name="sr_right_thumb_distal">
        <visual>
            <geometry name="thumb_distal_visual">
                <mesh filename="package://shadow_hand_ign/meshes/visual/thumb_distal.dae"/>
            </geometry>
        </visual>
        <collision>
            <geometry name="thumb_distal_collision">
                <mesh filename="package://shadow_hand_ign/meshes/collision/thumb_distal.stl"/>
            </geometry>
        </collision>
    </link>


    <!-- Thumb Joints -->
    <joint name="sr_right_thumb_joint1" type="revolute">
        <parent link="sr_right_palm"/>
        <child link="sr_right_thumb_base"/>
        <origin rpy="0 0.785398163397 0.0" xyz="0.034 -0.0085 0.029"/>
        <axis xyz="0 0 -1"/>
        <limit effort="4.0" lower="-1.0471975512" upper="1.0471975512" velocity="4.0"/>
    </joint>

    <joint name="sr_right_thumb_joint2" type="revolute">
        <parent link="sr_right_thumb_base"/>
        <child link="sr_right_thumb_proximal"/>
        <axis xyz="1 0 0"/>
        <limit effort="4.0" lower="0.0" upper="1.2217304764" velocity="4.0"/>
    </joint>

    <joint name="sr_right_thumb_joint3" type="revolute">
        <parent link="sr_right_thumb_proximal"/>
        <child link="sr_right_thumb_hub"/>
        <origin rpy="0 0 0" xyz="0 0 0.038"/>
        <axis xyz="1 0 0"/>
        <limit effort="4.0" lower="-0.209439510239" upper="0.209439510239" velocity="4.0"/>
    </joint>

    <joint name="sr_right_thumb_joint4" type="revolute">
        <parent link="sr_right_thumb_hub"/>
        <child link="sr_right_thumb_middle"/>
        <axis xyz="0 -1 0"/>
        <limit effort="4.0" lower="-0.698131700798" upper="0.698131700798" velocity="2.0"/>
    </joint>

    <joint name="sr_right_thumb_joint5" type="revolute">
        <parent link="sr_right_thumb_middle"/>
        <child link="sr_right_thumb_distal"/>
        <origin rpy="0 0 -1.57079632679" xyz="0 0 0.032"/>
        <axis xyz="1 0 0"/>
        <limit effort="4.0" lower="0" upper="1.57079632679" velocity="4.0"/>
    </joint>


    <!-- Index Finger Links -->
    <link name="sr_right_index_finger_knuckle">
        <visual>
            <origin rpy="0 0 0" xyz="0 0 0.0005"/>
            <geometry name="index_finger_knuckle_visual">
                <mesh filename="package://shadow_hand_ign/meshes/visual/knuckle.dae"/>
            </geometry>
        </visual>
        <collision>
            <origin rpy="0 0 0" xyz="0 0 0.0005"/>
            <geometry name="index_finger_knuckle_collision">
                <mesh filename="package://shadow_hand_ign/meshes/collision/knuckle.stl"/>
            </geometry>
        </collision>
    </link>

    <link name="sr_right_index_finger_proximal">
        <visual>
            <geometry name="index_finger_proximal_visual">
                <mesh filename="package://shadow_hand_ign/meshes/visual/finger_proximal.dae"/>
            </geometry>
        </visual>
        <collision>
            <geometry name="index_finger_proximal_collision">
                <mesh filename="package://shadow_hand_ign/meshes/collision/finger_proximal.stl"/>
            </geometry>
        </collision>
    </link>

    <link name="sr_right_index_finger_middle">
        <visual>
            <geometry name="index_finger_middle_visual">
                <mesh filename="package://shadow_hand_ign/meshes/visual/finger_middle.dae"/>
            </geometry>
        </visual>
        <collision>
            <geometry name="index_finger_middle_collision">
                <mesh filename="package://shadow_hand_ign/meshes/collision/finger_middle.stl"/>
            </geometry>
        </collision>
    </link>

    <link name="sr_right_index_finger_distal">
        <visual>
            <geometry name="index_finger_distal_visual">
                <mesh filename="package://shadow_hand_ign/meshes/visual/finger_distal.dae"/>
            </geometry>
        </visual>
        <collision>
            <geometry name="index_finger_distal_collision">
                <mesh filename="package://shadow_hand_ign/meshes/collision/finger_distal.stl"/>
            </geometry>
        </collision>
    </link>


    <!-- Index Finger Joints -->
    <joint name="sr_right_index_finger_joint1" type="revolute">
        <parent link="sr_right_palm"/>
        <child link="sr_right_index_finger_knuckle"/>
        <origin rpy="0 0 0" xyz="0.033 0 0.095"/>
        <axis xyz="0 -1 0"/>
        <limit effort="4.0" lower="-0.349065850399" upper="0.349065850399" velocity="2.0"/>
    </joint>

    <joint name="sr_right_index_finger_join2" type="revolute">
        <parent link="sr_right_index_finger_knuckle"/>
        <child link="sr_right_index_finger_proximal"/>
        <axis xyz="1 0 0"/>
        <limit effort="4.0" lower="0" upper="1.57079632679" velocity="2.0"/>
    </joint>

    <joint name="sr_right_index_finger_joint3" type="revolute">
        <parent link="sr_right_index_finger_proximal"/>
        <child link="sr_right_index_finger_middle"/>
        <origin rpy="0 0 0" xyz="0 0 0.045"/>
        <axis xyz="1 0 0"/>
        <limit effort="4.0" lower="0" upper="1.57079632679" velocity="2.0"/>
    </joint>

    <joint name="sr_right_index_finger_joint4" type="revolute">
        <parent link="sr_right_index_finger_middle"/>
        <child link="sr_right_index_finger_distal"/>
        <origin rpy="0 0 0" xyz="0 0 0.025"/>
        <axis xyz="1 0 0"/>
        <limit effort="4.0" lower="0" upper="1.57079632679" velocity="2.0"/>
    </joint>


    <!-- Middle Finger Links -->
    <link name="sr_right_middle_finger_knuckle">
        <visual>
            <origin rpy="0 0 0" xyz="0 0 0.0005"/>
            <geometry name="middle_finger_knuckle_visual">
                <mesh filename="package://shadow_hand_ign/meshes/visual/knuckle.dae"/>
            </geometry>
        </visual>
        <collision>
            <origin rpy="0 0 0" xyz="0 0 0.0005"/>
            <geometry name="middle_finger_knuckle_collision">
                <mesh filename="package://shadow_hand_ign/meshes/collision/knuckle.stl"/>
            </geometry>
        </collision>
    </link>

    <link name="sr_right_middle_finger_proximal">
        <visual>
            <geometry name="middle_finger_proximal_visual">
                <mesh filename="package://shadow_hand_ign/meshes/visual/finger_proximal.dae"/>
            </geometry>
        </visual>
        <collision>
            <geometry name="middle_finger_proximal_collision">
                <mesh filename="package://shadow_hand_ign/meshes/collision/finger_proximal.stl"/>
            </geometry>
        </collision>
    </link>

    <link name="sr_right_middle_finger_middle">
        <visual>
            <geometry name="middle_finger_middle_visual">
                <mesh filename="package://shadow_hand_ign/meshes/visual/finger_middle.dae"/>
            </geometry>
        </visual>
        <collision>
            <geometry name="middle_finger_middle_collision">
                <mesh filename="package://shadow_hand_ign/meshes/collision/finger_middle.stl"/>
            </geometry>
        </collision>
    </link>

    <link name="sr_right_middle_finger_distal">
        <visual>
            <geometry name="middle_finger_distal_visual">
                <mesh filename="package://shadow_hand_ign/meshes/visual/finger_distal.dae"/>
            </geometry>
        </visual>
        <collision>
            <geometry name="middle_finger_distal_collision">
                <mesh filename="package://shadow_hand_ign/meshes/collision/finger_distal.stl"/>
            </geometry>
        </collision>
    </link>


    <!-- Middle Finger Joints -->
    <joint name="sr_right_middle_finger_joint1" type="revolute">
        <parent link="sr_right_palm"/>
        <child link="sr_right_middle_finger_knuckle"/>
        <origin rpy="0 0 0" xyz="0.011 0 0.099"/>
        <axis xyz="0 -1 0"/>
        <limit effort="4.0" lower="-0.349065850399" upper="0.349065850399" velocity="2.0"/>
    </joint>

    <joint name="sr_right_middle_finger_joint2" type="revolute">
        <parent link="sr_right_middle_finger_knuckle"/>
        <child link="sr_right_middle_finger_proximal"/>
        <axis xyz="1 0 0"/>
        <limit effort="4.0" lower="0" upper="1.57079632679" velocity="2.0"/>
    </joint>

    <joint name="sr_right_middle_finger_joint3" type="revolute">
        <parent link="sr_right_middle_finger_proximal"/>
        <child link="sr_right_middle_finger_middle"/>
        <origin rpy="0 0 0" xyz="0 0 0.045"/>
        <axis xyz="1 0 0"/>
        <limit effort="4.0" lower="0" upper="1.57079632679" velocity="2.0"/>
    </joint>

    <joint name="sr_right_middle_finger_joint4" type="revolute">
        <parent link="sr_right_middle_finger_middle"/>
        <child link="sr_right_middle_finger_distal"/>
        <origin rpy="0 0 0" xyz="0 0 0.025"/>
        <axis xyz="1 0 0"/>
        <limit effort="4.0" lower="0" upper="1.57079632679" velocity="2.0"/>
    </joint>


    <!-- Ring Finger Links -->
    <link name="sr_right_ring_finger_knuckle">
        <visual>
            <origin rpy="0 0 0" xyz="0 0 0.0005"/>
            <geometry name="ring_finger_knuckle_visual">
                <mesh filename="package://shadow_hand_ign/meshes/visual/knuckle.dae"/>
            </geometry>
        </visual>
        <collision>
            <origin rpy="0 0 0" xyz="0 0 0.0005"/>
            <geometry name="ring_finger_knuckle_collision">
                <mesh filename="package://shadow_hand_ign/meshes/collision/knuckle.stl"/>
            </geometry>
        </collision>
    </link>

    <link name="sr_right_ring_finger_proximal">
        <visual>
            <geometry name="ring_finger_proximal_visual">
                <mesh filename="package://shadow_hand_ign/meshes/visual/finger_proximal.dae"/>
            </geometry>
        </visual>
        <collision>
            <geometry name="ring_finger_proximal_collision">
                <mesh filename="package://shadow_hand_ign/meshes/collision/finger_proximal.stl"/>
            </geometry>
        </collision>
    </link>

    <link name="sr_right_ring_finger_middle">
        <visual>
            <geometry name="ring_finger_middle_visual">
                <mesh filename="package://shadow_hand_ign/meshes/visual/finger_middle.dae"/>
            </geometry>
        </visual>
        <collision>
            <geometry name="ring_finger_middle_collision">
                <mesh filename="package://shadow_hand_ign/meshes/collision/finger_middle.stl"/>
            </geometry>
        </collision>
    </link>

    <link name="sr_right_ring_finger_distal">
        <visual>
            <geometry name="ring_finger_distal_visual">
                <mesh filename="package://shadow_hand_ign/meshes/visual/finger_distal.dae"/>
            </geometry>
        </visual>
        <collision>
            <geometry name="ring_finger_distal_collision">
                <mesh filename="package://shadow_hand_ign/meshes/collision/finger_distal.stl"/>
            </geometry>
        </collision>
    </link>


    <!-- Ring Finger Joints -->
    <joint name="sr_right_ring_finger_joint1" type="revolute">
        <parent link="sr_right_palm"/>
        <child link="sr_right_ring_finger_knuckle"/>
        <origin rpy="0 0 0" xyz="-0.011 0 0.095"/>
        <axis xyz="0 1 0"/>
        <limit effort="4.0" lower="-0.349065850399" upper="0.349065850399" velocity="2.0"/>
    </joint>

    <joint name="sr_right_ring_finger_joint2" type="revolute">
        <parent link="sr_right_ring_finger_knuckle"/>
        <child link="sr_right_ring_finger_proximal"/>
        <axis xyz="1 0 0"/>
        <limit effort="4.0" lower="0" upper="1.57079632679" velocity="2.0"/>
    </joint>

    <joint name="sr_right_ring_finger_joint3" type="revolute">
        <parent link="sr_right_ring_finger_proximal"/>
        <child link="sr_right_ring_finger_middle"/>
        <origin rpy="0 0 0" xyz="0 0 0.045"/>
        <axis xyz="1 0 0"/>
        <limit effort="4.0" lower="0" upper="1.57079632679" velocity="2.0"/>
    </joint>

    <joint name="sr_right_ring_finger_joint4" type="revolute">
        <parent link="sr_right_ring_finger_middle"/>
        <child link="sr_right_ring_finger_distal"/>
        <origin rpy="0 0 0" xyz="0 0 0.025"/>
        <axis xyz="1 0 0"/>
        <limit effort="4.0" lower="0" upper="1.57079632679" velocity="2.0"/>
    </joint>


    <!-- Little Finger Links -->
    <link name="sr_right_little_finger_metacarpal">
        <visual>
            <geometry name="little_finger_metacarpal_visual">
                <mesh filename="package://shadow_hand_ign/meshes/visual/metacarpal.dae"/>
            </geometry>
        </visual>
        <collision>
            <geometry name="little_finger_metacarpal_collision">
                <mesh filename="package://shadow_hand_ign/meshes/collision/metacarpal.stl"/>
            </geometry>
        </collision>
    </link>

    <link name="sr_right_little_finger_knuckle">
        <visual>
            <origin rpy="0 0 0" xyz="0 0 0.0005"/>
            <geometry name="little_finger_knuckle_visual">
                <mesh filename="package://shadow_hand_ign/meshes/visual/knuckle.dae"/>
            </geometry>
        </visual>
        <collision>
            <origin rpy="0 0 0" xyz="0 0 0.0005"/>
            <geometry name="little_finger_knuckle_collision">
                <mesh filename="package://shadow_hand_ign/meshes/collision/knuckle.stl"/>
            </geometry>
        </collision>
    </link>

    <link name="sr_right_little_finger_proximal">
        <visual>
            <geometry name="little_finger_proximal_visual">
                <mesh filename="package://shadow_hand_ign/meshes/visual/finger_proximal.dae"/>
            </geometry>
        </visual>
        <collision>
            <geometry name="little_finger_proximal_collision">
                <mesh filename="package://shadow_hand_ign/meshes/collision/finger_proximal.stl"/>
            </geometry>
        </collision>
    </link>

    <link name="sr_right_little_finger_middle">
        <visual>
            <geometry name="little_finger_middle_visual">
                <mesh filename="package://shadow_hand_ign/meshes/visual/finger_middle.dae"/>
            </geometry>
        </visual>
        <collision>
            <geometry name="little_finger_middle_collision">
                <mesh filename="package://shadow_hand_ign/meshes/collision/finger_middle.stl"/>
            </geometry>
        </collision>
    </link>

    <link name="sr_right_little_finger_distal">
        <visual>
            <geometry name="little_finger_distal_visual">
                <mesh filename="package://shadow_hand_ign/meshes/visual/finger_distal.dae"/>
            </geometry>
        </visual>
        <collision>
            <geometry name="little_finger_distal_collision">
                <mesh filename="package://shadow_hand_ign/meshes/collision/finger_distal.stl"/>
            </geometry>
        </collision>
    </link>


    <!-- Little Finger Joints -->
    <joint name="sr_right_little_finger_joint1" type="revolute">
        <parent link="sr_right_palm"/>
        <child link="sr_right_little_finger_metacarpal"/>
        <origin rpy="0 0 0" xyz="-0.033 0 0.02071"/>
        <axis xyz="0.573576436 0 0.819152044"/>
        <limit effort="4.0" lower="0" upper="0.785398163397" velocity="2.0"/>
    </joint>

    <joint name="sr_right_little_finger_joint2" type="revolute">
        <parent link="sr_right_little_finger_metacarpal"/>
        <child link="sr_right_little_finger_knuckle"/>
        <origin rpy="0 0 0" xyz="0 0 0.06579"/>
        <axis xyz="0 1 0"/>
        <limit effort="4.0" lower="-0.349065850399" upper="0.349065850399" velocity="2.0"/>
    </joint>

    <joint name="sr_right_little_finger_joint3" type="revolute">
        <parent link="sr_right_little_finger_knuckle"/>
        <child link="sr_right_little_finger_proximal"/>
        <axis xyz="1 0 0"/>
        <limit effort="4.0" lower="0" upper="1.57079632679" velocity="2.0"/>
    </joint>

    <joint name="sr_right_little_finger_joint4" type="revolute">
        <parent link="sr_right_little_finger_proximal"/>
        <child link="sr_right_little_finger_middle"/>
        <origin rpy="0 0 0" xyz="0 0 0.045"/>
        <axis xyz="1 0 0"/>
        <limit effort="4.0" lower="0" upper="1.57079632679" velocity="2.0"/>
    </joint>

    <joint name="sr_right_little_finger_joint5" type="revolute">
        <parent link="sr_right_little_finger_middle"/>
        <child link="sr_right_little_finger_distal"/>
        <origin rpy="0 0 0" xyz="0 0 0.025"/>
        <axis xyz="1 0 0"/>
        <limit effort="4.0" lower="0" upper="1.57079632679" velocity="2.0"/>
    </joint>
</robot>
