<?xml version="1.0" ?>
<!-- =================================================================================== -->
<!-- |    This document was autogenerated by xacro from peg_lwr_robot.urdf.xacro       | -->
<!-- |    EDITING THIS FILE BY HAND IS NOT RECOMMENDED                                 | -->
<!-- =================================================================================== -->
<robot name="kuka_lwr_peg_robot" xmlns:xacro="http://ros.org/wiki/xacro">
  <!-- Include all models -->
  <!-- utils /-->
  <!-- Little helper macro to define the inertia matrix needed for links. -->
  <!-- length is along the y-axis! -->
  <material name="Kuka/DarkGrey">
    <color rgba="0.3 0.3 0.3 1.0"/>
  </material>
  <material name="Kuka/LightGrey">
    <color rgba="0.8 0.8 0.8 1.0"/>
  </material>
  <material name="Kuka/Red">
    <color rgba="0.3 0.3 0.3 1.0"/>
  </material>
  <material name="Kuka/Black">
    <color rgba="0 0 0 1.0"/>
  </material>
  <material name="Kuka/Orange">
    <color rgba="1.0 0.487 0 1.0"/>
  </material>
  <material name="Kuka/Silver">
    <color rgba="1.0 1.0 1.0 1.0"/>
  </material>
  <material name="Kuka/Grey">
    <color rgba="0.7 0.7 0.7 1.0"/>
  </material>
  <material name="Kuka/Blue">
    <color rgba="0.0 0.0 0.8 1.0"/>
  </material>
  <!-- gazebo and transmission models /-->
  <!-- properties /-->
  <!-- reflex to stiffness -->
  <!-- URDF model /-->
  <!-- using the models -->
  <link name="world"/>
  <gazebo reference="world">
    <static>true</static>
    <turnGravityOff>true</turnGravityOff>
  </gazebo>
  <!-- First (shoulder) element of the arm. Fixed to its parent. -->
  <joint name="lwr_base_joint" type="fixed">
    <origin rpy="0 0 0" xyz="0 0 0"/>
    <origin rpy="0 0 0" xyz="0 0 0"/>
    <parent link="world"/>
    <child link="lwr_base_link"/>
  </joint>
  <link name="lwr_base_link">
    <inertial>
      <mass value="2.0"/>
      <origin xyz="0 0 0.055"/>
      <inertia ixx="0.00381666666667" ixy="0" ixz="0" iyy="0.0036" iyz="0" izz="0.00381666666667"/>
    </inertial>
    <visual>
      <origin rpy="0 0 3.14159265359" xyz="0 0 0"/>
      <geometry>
        <mesh filename="package://lwr_description/meshes/base.dae"/>
      </geometry>
      <material name="Kuka/Orange"/>
    </visual>
    <collision>
      <origin rpy="0 0 3.14159265359" xyz="0 0 0.055"/>
      <geometry>
        <!-- <mesh filename="package://lwr_description/meshes/convex/arm_base_convex.stl"/> -->
        <cylinder length="0.11" radius="0.07"/>
      </geometry>
    </collision>
  </link>
  <!-- Second segment of the arm. Joint along z-axis -->
  <joint name="lwr_0_joint" type="revolute">
    <origin rpy="0 0 0" xyz="0 0 0.11"/>
    <axis xyz="0 0 1"/>
    <limit effort="176" lower="-2.96705972839" upper="2.96705972839" velocity="1.91986217719"/>
    <dynamics damping="1.0" friction="10.0"/>
    <parent link="lwr_base_link"/>
    <child link="lwr_1_link"/>
  </joint>
  <joint name="lwr_0_joint_stiffness" type="revolute">
    <axis xyz="0 0 1"/>
    <limit effort="0" lower="0" upper="5000" velocity="20000"/>
    <safety_controller k_position="30" k_velocity="30" soft_lower_limit="0" soft_upper_limit="5000"/>
    <parent link="lwr_base_link"/>
    <child link="lwr_1_link_dummy"/>
  </joint>
  <joint name="lwr_0_joint_damping" type="revolute">
    <axis xyz="0 0 1"/>
    <limit effort="0" lower="0" upper="500" velocity="20000"/>
    <safety_controller k_position="30" k_velocity="30" soft_lower_limit="0" soft_upper_limit="500"/>
    <parent link="lwr_base_link"/>
    <child link="lwr_1_link_damping"/>
  </joint>
  <joint name="lwr_0_joint_torque" type="revolute">
    <axis xyz="0 0 1"/>
    <limit effort="176" lower="-2.96705972839" upper="2.96705972839" velocity="1.91986217719"/>
    <dynamics damping="1.0" friction="10.0"/>
    <parent link="lwr_base_link"/>
    <child link="lwr_1_link_torque"/>
  </joint>
  <link name="lwr_1_link_dummy"/>
  <link name="lwr_1_link_damping"/>
  <link name="lwr_1_link_torque"/>
  <link name="lwr_1_link">
    <inertial>
      <mass value="2.0"/>
      <origin rpy="0 0 0" xyz="0 -0.06 0.130"/>
      <inertia ixx="0.0136666666667" ixy="0" ixz="0" iyy="0.003" iyz="0" izz="0.0118666666667"/>
    </inertial>
    <visual>
      <origin rpy="0 0 3.14159265359" xyz="0 0 -0.008"/>
      <geometry>
        <mesh filename="package://lwr_description/meshes/link_1.dae"/>
      </geometry>
      <material name="Kuka/Orange"/>
    </visual>
    <collision>
      <origin rpy="0 0 0" xyz="0 0 0.0"/>
      <geometry>
        <!--mesh filename="package://lwr_description/meshes/convex/arm_segment_a_convex.stl"/-->
        <sphere radius="0.07"/>
      </geometry>
    </collision>
    <collision>
      <origin rpy="0 0 0" xyz="0 0.06 0.2"/>
      <geometry>
        <sphere radius="0.07"/>
      </geometry>
    </collision>
    <collision>
      <origin rpy="-0.291 0 0" xyz="0 0.03 0.1"/>
      <geometry>
        <cylinder length="0.208" radius="0.07"/>
      </geometry>
    </collision>
  </link>
  <!-- Third segment of the arm. Joint along y-axis -->
  <joint name="lwr_1_joint" type="revolute">
    <origin rpy="0 0 0" xyz="0 0 0.2005"/>
    <axis xyz="0 -1 0"/>
    <limit effort="176" lower="-2.09439510239" upper="2.09439510239" velocity="1.91986217719"/>
    <dynamics damping="1.0" friction="10.0"/>
    <parent link="lwr_1_link"/>
    <child link="lwr_2_link"/>
  </joint>
  <joint name="lwr_1_joint_stiffness" type="revolute">
    <axis xyz="0 0 1"/>
    <limit effort="0" lower="0" upper="5000" velocity="20000"/>
    <safety_controller k_position="30" k_velocity="30" soft_lower_limit="0" soft_upper_limit="5000"/>
    <parent link="lwr_1_link"/>
    <child link="lwr_2_link_dummy"/>
  </joint>
  <joint name="lwr_1_joint_damping" type="revolute">
    <axis xyz="0 0 1"/>
    <limit effort="0" lower="0" upper="500" velocity="20000"/>
    <safety_controller k_position="30" k_velocity="30" soft_lower_limit="0" soft_upper_limit="500"/>
    <parent link="lwr_1_link"/>
    <child link="lwr_2_link_damping"/>
  </joint>
  <joint name="lwr_1_joint_torque" type="revolute">
    <axis xyz="0 -1 0"/>
    <limit effort="176" lower="-2.09439510239" upper="2.09439510239" velocity="1.91986217719"/>
    <dynamics damping="1.0" friction="10.0"/>
    <parent link="lwr_1_link"/>
    <child link="lwr_2_link_torque"/>
  </joint>
  <link name="lwr_2_link_dummy"/>
  <link name="lwr_2_link_damping"/>
  <link name="lwr_2_link_torque"/>
  <link name="lwr_2_link">
    <inertial>
      <mass value="2.0"/>
      <origin rpy="0 0 0" xyz="0 0.06 0.07"/>
      <inertia ixx="0.0136666666667" ixy="0" ixz="0" iyy="0.003" iyz="0" izz="0.0118666666667"/>
    </inertial>
    <visual>
      <origin rpy="0 0 3.14159265359" xyz="0 0 0.0"/>
      <geometry>
        <mesh filename="package://lwr_description/meshes/link_2.dae"/>
      </geometry>
      <!--material name="Kuka/Orange"/-->
    </visual>
    <collision>
      <origin rpy="0 0 0" xyz="0 0 0.2"/>
      <geometry>
        <!--mesh filename="package://lwr_description/meshes/convex/arm_segment_b_convex.stl"/-->
        <sphere radius="0.07"/>
      </geometry>
    </collision>
    <collision>
      <origin rpy="0 0 0" xyz="0 -0.06 0.0"/>
      <geometry>
        <sphere radius="0.07"/>
      </geometry>
    </collision>
    <collision>
      <origin rpy="-0.291 0 0" xyz="0 -0.03 0.1"/>
      <geometry>
        <cylinder length="0.208" radius="0.07"/>
      </geometry>
    </collision>
  </link>
  <!-- Fourth element of the arm. z-axis -->
  <joint name="lwr_2_joint" type="revolute">
    <origin rpy="0 0 0" xyz="0 0 0.20"/>
    <axis xyz="0 0 1"/>
    <limit effort="100" lower="-2.96705972839" upper="2.96705972839" velocity="2.23402144255"/>
    <dynamics damping="1.0" friction="10.0"/>
    <parent link="lwr_2_link"/>
    <child link="lwr_3_link"/>
  </joint>
  <joint name="lwr_2_joint_stiffness" type="revolute">
    <axis xyz="0 0 1"/>
    <limit effort="0" lower="0" upper="5000" velocity="20000"/>
    <safety_controller k_position="30" k_velocity="30" soft_lower_limit="0" soft_upper_limit="5000"/>
    <parent link="lwr_2_link"/>
    <child link="lwr_3_link_dummy"/>
  </joint>
  <joint name="lwr_2_joint_damping" type="revolute">
    <axis xyz="0 0 1"/>
    <limit effort="0" lower="0" upper="500" velocity="20000"/>
    <safety_controller k_position="30" k_velocity="30" soft_lower_limit="0" soft_upper_limit="500"/>
    <parent link="lwr_2_link"/>
    <child link="lwr_3_link_damping"/>
  </joint>
  <joint name="lwr_2_joint_torque" type="revolute">
    <axis xyz="0 0 1"/>
    <limit effort="0" lower="0" upper="5000" velocity="20000"/>
    <safety_controller k_position="30" k_velocity="30" soft_lower_limit="0" soft_upper_limit="5000"/>
    <parent link="lwr_2_link"/>
    <child link="lwr_3_link_torque"/>
  </joint>
  <link name="lwr_3_link_dummy"/>
  <link name="lwr_3_link_damping"/>
  <link name="lwr_3_link_torque"/>
  <link name="lwr_3_link">
    <inertial>
      <mass value="2.0"/>
      <origin rpy="0 0 0" xyz="0 0.06 0.130"/>
      <inertia ixx="0.0136666666667" ixy="0" ixz="0" iyy="0.003" iyz="0" izz="0.0118666666667"/>
    </inertial>
    <visual>
      <origin rpy="0 0 3.14159265359" xyz="0 0 -0.008"/>
      <geometry>
        <mesh filename="package://lwr_description/meshes/link_3.dae"/>
      </geometry>
      <material name="Kuka/Orange"/>
    </visual>
    <collision>
      <origin rpy="0 0 0" xyz="0 0 0.0"/>
      <geometry>
        <!--mesh filename="package://lwr_description/meshes/convex/arm_segment_a_convex.stl"/-->
        <sphere radius="0.07"/>
      </geometry>
    </collision>
    <collision>
      <origin rpy="0 0 0" xyz="0 -0.06 0.2"/>
      <geometry>
        <sphere radius="0.07"/>
      </geometry>
    </collision>
    <collision>
      <origin rpy="0.291 0 0" xyz="0 -0.03 0.1"/>
      <geometry>
        <cylinder length="0.208" radius="0.07"/>
      </geometry>
    </collision>
  </link>
  <!-- fifth element of the arm. x-axis -->
  <joint name="lwr_3_joint" type="revolute">
    <origin rpy="0 0 0" xyz="0 0 0.20"/>
    <axis xyz="0 1 0"/>
    <limit effort="100" lower="-2.09439510239" upper="2.09439510239" velocity="2.23402144255"/>
    <dynamics damping="1.0" friction="10.0"/>
    <parent link="lwr_3_link"/>
    <child link="lwr_4_link"/>
  </joint>
  <joint name="lwr_3_joint_stiffness" type="revolute">
    <axis xyz="0 0 1"/>
    <limit effort="0" lower="0" upper="5000" velocity="20000"/>
    <safety_controller k_position="30" k_velocity="30" soft_lower_limit="0" soft_upper_limit="5000"/>
    <parent link="lwr_3_link"/>
    <child link="lwr_4_link_dummy"/>
  </joint>
  <joint name="lwr_3_joint_damping" type="revolute">
    <axis xyz="0 0 1"/>
    <limit effort="0" lower="0" upper="500" velocity="20000"/>
    <safety_controller k_position="30" k_velocity="30" soft_lower_limit="0" soft_upper_limit="500"/>
    <parent link="lwr_3_link"/>
    <child link="lwr_4_link_damping"/>
  </joint>
  <joint name="lwr_3_joint_torque" type="revolute">
    <axis xyz="0 1 0"/>
    <limit effort="100" lower="-2.09439510239" upper="2.09439510239" velocity="2.23402144255"/>
    <dynamics damping="1.0" friction="10.0"/>
    <parent link="lwr_3_link"/>
    <child link="lwr_4_link_torque"/>
  </joint>
  <link name="lwr_4_link_dummy"/>
  <link name="lwr_4_link_damping"/>
  <link name="lwr_4_link_torque"/>
  <link name="lwr_4_link">
    <inertial>
      <mass value="2.0"/>
      <origin rpy="0 0 0" xyz="0 -0.06 0.07"/>
      <inertia ixx="0.0136666666667" ixy="0" ixz="0" iyy="0.003" iyz="0" izz="0.0118666666667"/>
    </inertial>
    <visual>
      <origin rpy="0 0 3.14159265359" xyz="0 0 0.0"/>
      <geometry>
        <mesh filename="package://lwr_description/meshes/link_4.dae"/>
      </geometry>
      <material name="Kuka/Orange"/>
    </visual>
    <collision>
      <origin rpy="0 0 0" xyz="0 0 0.2"/>
      <geometry>
        <!--mesh filename="package://lwr_description/meshes/convex/arm_segment_b_convex.stl"/-->
        <sphere radius="0.07"/>
      </geometry>
    </collision>
    <collision>
      <origin rpy="0 0 0" xyz="0 0.06 0.0"/>
      <geometry>
        <sphere radius="0.07"/>
      </geometry>
    </collision>
    <collision>
      <origin rpy="0.291 0 0" xyz="0 0.03 0.1"/>
      <geometry>
        <cylinder length="0.208" radius="0.07"/>
      </geometry>
    </collision>
  </link>
  <!-- Sixth element of the arm. z-axis -->
  <joint name="lwr_4_joint" type="revolute">
    <origin rpy="0 0 0" xyz="0 0 0.20"/>
    <axis xyz="0 0 1"/>
    <limit effort="100" lower="-2.96705972839" upper="2.96705972839" velocity="3.56047167407"/>
    <dynamics damping="1.0" friction="10.0"/>
    <parent link="lwr_4_link"/>
    <child link="lwr_5_link"/>
  </joint>
  <joint name="lwr_4_joint_stiffness" type="revolute">
    <axis xyz="0 0 1"/>
    <limit effort="0" lower="0" upper="5000" velocity="20000"/>
    <safety_controller k_position="30" k_velocity="30" soft_lower_limit="0" soft_upper_limit="5000"/>
    <parent link="lwr_4_link"/>
    <child link="lwr_5_link_dummy"/>
  </joint>
  <joint name="lwr_4_joint_damping" type="revolute">
    <axis xyz="0 0 1"/>
    <limit effort="0" lower="0" upper="500" velocity="20000"/>
    <safety_controller k_position="30" k_velocity="30" soft_lower_limit="0" soft_upper_limit="500"/>
    <parent link="lwr_4_link"/>
    <child link="lwr_5_link_damping"/>
  </joint>
  <joint name="lwr_4_joint_torque" type="revolute">
    <axis xyz="0 0 1"/>
    <limit effort="0" lower="0" upper="500" velocity="20000"/>
    <safety_controller k_position="30" k_velocity="30" soft_lower_limit="0" soft_upper_limit="500"/>
    <parent link="lwr_4_link"/>
    <child link="lwr_5_link_torque"/>
  </joint>
  <link name="lwr_5_link_dummy"/>
  <link name="lwr_5_link_damping"/>
  <link name="lwr_5_link_torque"/>
  <link name="lwr_5_link">
    <inertial>
      <mass value="2.0"/>
      <origin rpy="0 0 0" xyz="0 0 0.124"/>
      <inertia ixx="0.0126506666667" ixy="0" ixz="0" iyy="0.003" iyz="0" izz="0.0108506666667"/>
    </inertial>
    <visual>
      <origin rpy="0 0 3.14159265359" xyz="0 0 -0.008"/>
      <geometry name="lwr_5_geom">
        <mesh filename="package://lwr_description/meshes/link_5.dae"/>
      </geometry>
      <material name="Kuka/Orange"/>
    </visual>
    <collision>
      <origin rpy="0 0 0" xyz="0 0 0.0"/>
      <geometry>
        <!--mesh filename="package://lwr_description/meshes/convex/arm_segment_last_convex.stl"/-->
        <sphere radius="0.07"/>
      </geometry>
    </collision>
    <collision>
      <origin rpy="0 0 0" xyz="0 0.04 0.19"/>
      <geometry>
        <sphere radius="0.07"/>
      </geometry>
    </collision>
    <collision>
      <origin rpy="-0.207 0 0" xyz="0 0.02 0.095"/>
      <geometry>
        <cylinder length="0.198" radius="0.07"/>
      </geometry>
    </collision>
  </link>
  <!-- Seventh element of the arm. z-axis -->
  <joint name="lwr_5_joint" type="revolute">
    <origin rpy="0 0 0" xyz="0 0 0.19"/>
    <axis xyz="0 -1 0"/>
    <limit effort="38" lower="-2.09439510239" upper="2.09439510239" velocity="3.21140582367"/>
    <dynamics damping="1.0" friction="10.0"/>
    <parent link="lwr_5_link"/>
    <child link="lwr_6_link"/>
  </joint>
  <joint name="lwr_5_joint_stiffness" type="revolute">
    <axis xyz="0 0 1"/>
    <limit effort="0" lower="0" upper="5000" velocity="20000"/>
    <safety_controller k_position="30" k_velocity="30" soft_lower_limit="0" soft_upper_limit="5000"/>
    <parent link="lwr_5_link"/>
    <child link="lwr_6_link_dummy"/>
  </joint>
  <joint name="lwr_5_joint_damping" type="revolute">
    <axis xyz="0 0 1"/>
    <limit effort="0" lower="0" upper="500" velocity="20000"/>
    <safety_controller k_position="30" k_velocity="30" soft_lower_limit="0" soft_upper_limit="500"/>
    <parent link="lwr_5_link"/>
    <child link="lwr_6_link_damping"/>
  </joint>
  <joint name="lwr_5_joint_torque" type="revolute">
    <axis xyz="0 0 1"/>
    <limit effort="0" lower="0" upper="500" velocity="20000"/>
    <safety_controller k_position="30" k_velocity="30" soft_lower_limit="0" soft_upper_limit="500"/>
    <parent link="lwr_5_link"/>
    <child link="lwr_6_link_torque"/>
  </joint>
  <link name="lwr_6_link_dummy"/>
  <link name="lwr_6_link_damping"/>
  <link name="lwr_6_link_torque"/>
  <link name="lwr_6_link">
    <inertial>
      <mass value="0.2"/>
      <origin rpy="0 0 0" xyz="0 0 0.0625"/>
      <inertia ixx="0.000520833333333" ixy="0" ixz="0" iyy="0.000520833333333" iyz="0" izz="0.000520833333333"/>
    </inertial>
    <visual>
      <origin rpy="0 0 3.14159265359" xyz="0 0 0"/>
      <geometry>
        <mesh filename="package://lwr_description/meshes/link_6.dae"/>
      </geometry>
      <material name="Kuka/Grey"/>
    </visual>
    <collision>
      <origin rpy="0 0 3.14159265359" xyz="0 0 0"/>
      <geometry>
        <mesh filename="package://lwr_description/meshes/convex/arm_wrist_convex.stl"/>
      </geometry>
    </collision>
  </link>
  <!-- Eighth element of the arm. z-axis -->
  <joint name="lwr_6_joint" type="revolute">
    <origin rpy="0 0 0" xyz="0 0 0.078"/>
    <axis xyz="0 0 1"/>
    <limit effort="38" lower="-2.96705972839" upper="2.96705972839" velocity="3.21140582367"/>
    <dynamics damping="1.0" friction="10.0"/>
    <parent link="lwr_6_link"/>
    <child link="lwr_7_link"/>
  </joint>
  <joint name="lwr_6_joint_stiffness" type="revolute">
    <axis xyz="0 0 1"/>
    <limit effort="0" lower="0" upper="5000" velocity="20000"/>
    <safety_controller k_position="30" k_velocity="30" soft_lower_limit="0" soft_upper_limit="5000"/>
    <parent link="lwr_6_link"/>
    <child link="lwr_7_link_dummy"/>
  </joint>
  <joint name="lwr_6_joint_damping" type="revolute">
    <axis xyz="0 0 1"/>
    <limit effort="0" lower="0" upper="500" velocity="20000"/>
    <safety_controller k_position="30" k_velocity="30" soft_lower_limit="0" soft_upper_limit="500"/>
    <parent link="lwr_6_link"/>
    <child link="lwr_7_link_damping"/>
  </joint>
  <joint name="lwr_6_joint_torque" type="revolute">
    <axis xyz="0 0 1"/>
    <limit effort="0" lower="0" upper="500" velocity="20000"/>
    <safety_controller k_position="30" k_velocity="30" soft_lower_limit="0" soft_upper_limit="500"/>
    <parent link="lwr_6_link"/>
    <child link="lwr_7_link_torque"/>
  </joint>
  <link name="lwr_7_link_dummy"/>
  <link name="lwr_7_link_damping"/>
  <link name="lwr_7_link_torque"/>
  <link name="lwr_7_link">
    <inertial>
      <mass value="0.2"/>
      <origin xyz="0 0 0"/>
      <inertia ixx="0.0333333333333" ixy="0" ixz="0" iyy="0.0333333333333" iyz="0" izz="0.0333333333333"/>
    </inertial>
    <visual>
      <origin rpy="0 0 3.14159265359" xyz="0 0 0"/>
      <geometry>
        <mesh filename="package://lwr_description/meshes/link_7.dae"/>
      </geometry>
      <material name="Kuka/DarkGrey"/>
    </visual>
    <collision>
      <origin rpy="0 0 3.14159265359" xyz="0 0 0"/>
      <geometry>
        <cylinder length="0.05" radius="0.04"/>
      </geometry>
    </collision>
  </link>
  <gazebo>
    <plugin filename="liblwr_hw_gazebo_plugin.so" name="lwr_lwr_hw_sim">
      <robotNamespace>lwr</robotNamespace>
    </plugin>
  </gazebo>
  <!--gazebo>
  			<plugin name="gazebo_ros_control" filename="libgazebo_ros_control.so">
   			 	<robotNamespace>${name}</robotNamespace>
 		 	</plugin>
		</gazebo-->
  <gazebo reference="lwr_base_link">
    <gravity>true</gravity>
  </gazebo>
  <gazebo reference="lwr_1_link">
    <gravity>true</gravity>
  </gazebo>
  <gazebo reference="lwr_2_link">
    <gravity>true</gravity>
  </gazebo>
  <gazebo reference="lwr_3_link">
    <gravity>true</gravity>
  </gazebo>
  <gazebo reference="lwr_4_link">
    <gravity>true</gravity>
  </gazebo>
  <gazebo reference="lwr_5_link">
    <gravity>true</gravity>
  </gazebo>
  <gazebo reference="lwr_6_link">
    <gravity>true</gravity>
  </gazebo>
  <gazebo reference="lwr_7_link">
    <gravity>true</gravity>
  </gazebo>
  <transmission name="lwr_0_trans">
    <type>transmission_interface/SimpleTransmission</type>
    <joint name="lwr_0_joint">
      <hardwareInterface>PositionJointInterface</hardwareInterface>
      <hardwareInterface>EffortJointInterface</hardwareInterface>
    </joint>
    <actuator name="lwr_0_motor">
      <mechanicalReduction>1</mechanicalReduction>
    </actuator>
  </transmission>
  <transmission name="lwr_1_trans">
    <type>transmission_interface/SimpleTransmission</type>
    <joint name="lwr_1_joint">
      <hardwareInterface>PositionJointInterface</hardwareInterface>
      <hardwareInterface>EffortJointInterface</hardwareInterface>
    </joint>
    <actuator name="lwr_1_motor">
      <mechanicalReduction>1</mechanicalReduction>
    </actuator>
  </transmission>
  <transmission name="lwr_2_trans">
    <type>transmission_interface/SimpleTransmission</type>
    <joint name="lwr_2_joint">
      <hardwareInterface>PositionJointInterface</hardwareInterface>
      <hardwareInterface>EffortJointInterface</hardwareInterface>
    </joint>
    <actuator name="lwr_2_motor">
      <mechanicalReduction>1</mechanicalReduction>
    </actuator>
  </transmission>
  <transmission name="lwr_3_trans">
    <type>transmission_interface/SimpleTransmission</type>
    <joint name="lwr_3_joint">
      <hardwareInterface>PositionJointInterface</hardwareInterface>
      <hardwareInterface>EffortJointInterface</hardwareInterface>
    </joint>
    <actuator name="lwr_3_motor">
      <mechanicalReduction>1</mechanicalReduction>
    </actuator>
  </transmission>
  <transmission name="lwr_4_trans">
    <type>transmission_interface/SimpleTransmission</type>
    <joint name="lwr_4_joint">
      <hardwareInterface>PositionJointInterface</hardwareInterface>
      <hardwareInterface>EffortJointInterface</hardwareInterface>
    </joint>
    <actuator name="lwr_4_motor">
      <mechanicalReduction>1</mechanicalReduction>
    </actuator>
  </transmission>
  <transmission name="lwr_5_trans">
    <type>transmission_interface/SimpleTransmission</type>
    <joint name="lwr_5_joint">
      <hardwareInterface>PositionJointInterface</hardwareInterface>
      <hardwareInterface>EffortJointInterface</hardwareInterface>
    </joint>
    <actuator name="lwr_5_motor">
      <mechanicalReduction>1</mechanicalReduction>
    </actuator>
  </transmission>
  <transmission name="lwr_6_trans">
    <type>transmission_interface/SimpleTransmission</type>
    <joint name="lwr_6_joint">
      <hardwareInterface>PositionJointInterface</hardwareInterface>
      <hardwareInterface>EffortJointInterface</hardwareInterface>
    </joint>
    <actuator name="lwr_6_motor">
      <mechanicalReduction>1</mechanicalReduction>
    </actuator>
  </transmission>
  <joint name="dummy_joint" type="fixed">
    <origin rpy="0 0 0" xyz="0 0 0.2"/>
    <parent link="lwr_7_link"/>
    <child link="dummy_link"/>
  </joint>
  <link name="dummy_link">
    <origin rpy="0 0 0" xyz="0 0 0"/>
    <visual>
      <origin rpy="0 0 0" xyz="0 0 -0.12"/>
      <geometry>
        <cylinder length="0.2" radius="0.01"/>
      </geometry>
      <material name="my_color">
        <color alpha="0.5" rgb="180 255 255"/>
      </material>
    </visual>
  </link>
  <gazebo reference="dummy_link">
    <gravity>true</gravity>
    <material>Gazebo/Grey</material>
  </gazebo>
  <joint name="lwr_peg_joint" type="fixed">
    <origin rpy="0 0 0" xyz="0 0 0"/>
    <parent link="dummy_link"/>
    <child link="lwr_peg_link"/>
  </joint>
  <link name="lwr_peg_link">
    <origin rpy="0 0 0" xyz="0 0 0"/>
    <inertial>
      <mass value="0.06"/>
      <origin xyz="0 0 0"/>
      <inertia ixx="0.01" ixy="0" ixz="0" iyy="0.01" iyz="0" izz="0.01"/>
    </inertial>
    <visual>
      <origin rpy="0 -1.57079632679 3.14159265359" xyz="0 0 0"/>
      <geometry>
        <mesh filename="package://peg_lwr_robot/meshes/peg.dae"/>
      </geometry>
    </visual>
    <collision>
      <geometry>
        <cylinder length="0.05" radius="0.04"/>
      </geometry>
    </collision>
  </link>
</robot>

